<?xml version="1.0" encoding="UTF-8"?>
<testng-results ignored="0" total="7" passed="4" failed="3" skipped="0">
  <reporter-output>
  </reporter-output>
  <suite started-at="2021-05-27T21:19:01 ICT" name="Default suite" finished-at="2021-05-27T21:20:20 ICT" duration-ms="79162">
    <groups>
    </groups>
    <test started-at="2021-05-27T21:19:01 ICT" name="Default test" finished-at="2021-05-27T21:20:20 ICT" duration-ms="79162">
      <class name="testAddstudent.TestAddStudent">
        <test-method is-config="true" signature="suiteSetup()[pri:0, instance:testAddstudent.TestAddStudent@5bd03f44]" started-at="2021-05-27T21:19:01 ICT" name="suiteSetup" finished-at="2021-05-27T21:19:12 ICT" duration-ms="10843" status="PASS">
          <reporter-output>
          </reporter-output>
        </test-method> <!-- suiteSetup -->
        <test-method signature="Testcase1()[pri:1, instance:testAddstudent.TestAddStudent@5bd03f44]" started-at="2021-05-27T21:19:12 ICT" name="Testcase1" finished-at="2021-05-27T21:19:22 ICT" duration-ms="9666" status="PASS">
          <reporter-output>
          </reporter-output>
        </test-method> <!-- Testcase1 -->
        <test-method signature="Testcase2()[pri:2, instance:testAddstudent.TestAddStudent@5bd03f44]" started-at="2021-05-27T21:19:22 ICT" name="Testcase2" finished-at="2021-05-27T21:19:31 ICT" duration-ms="9632" status="PASS">
          <reporter-output>
          </reporter-output>
        </test-method> <!-- Testcase2 -->
        <test-method signature="Testcase3()[pri:3, instance:testAddstudent.TestAddStudent@5bd03f44]" started-at="2021-05-27T21:19:31 ICT" name="Testcase3" finished-at="2021-05-27T21:19:41 ICT" duration-ms="9666" status="PASS">
          <reporter-output>
          </reporter-output>
        </test-method> <!-- Testcase3 -->
        <test-method signature="Testcase4()[pri:4, instance:testAddstudent.TestAddStudent@5bd03f44]" started-at="2021-05-27T21:19:41 ICT" name="Testcase4" finished-at="2021-05-27T21:19:51 ICT" duration-ms="9683" status="FAIL">
          <exception class="java.lang.AssertionError">
            <message>
              <![CDATA[expected [This account already exists] but found [wrong phone number format]]]>
            </message>
            <full-stacktrace>
              <![CDATA[java.lang.AssertionError: expected [This account already exists] but found [wrong phone number format]
at org.testng.Assert.fail(Assert.java:99)
at org.testng.Assert.failNotEquals(Assert.java:1037)
at org.testng.Assert.assertEqualsImpl(Assert.java:140)
at org.testng.Assert.assertEquals(Assert.java:122)
at org.testng.Assert.assertEquals(Assert.java:629)
at org.testng.Assert.assertEquals(Assert.java:639)
at testAddstudent.TestAddStudent.Testcase4(TestAddStudent.java:274)
at java.base/jdk.internal.reflect.NativeMethodAccessorImpl.invoke0(Native Method)
at java.base/jdk.internal.reflect.NativeMethodAccessorImpl.invoke(NativeMethodAccessorImpl.java:62)
at java.base/jdk.internal.reflect.DelegatingMethodAccessorImpl.invoke(DelegatingMethodAccessorImpl.java:43)
at java.base/java.lang.reflect.Method.invoke(Method.java:564)
at org.testng.internal.MethodInvocationHelper.invokeMethod(MethodInvocationHelper.java:133)
at org.testng.internal.TestInvoker.invokeMethod(TestInvoker.java:598)
at org.testng.internal.TestInvoker.invokeTestMethod(TestInvoker.java:173)
at org.testng.internal.MethodRunner.runInSequence(MethodRunner.java:46)
at org.testng.internal.TestInvoker$MethodInvocationAgent.invoke(TestInvoker.java:824)
at org.testng.internal.TestInvoker.invokeTestMethods(TestInvoker.java:146)
at org.testng.internal.TestMethodWorker.invokeTestMethods(TestMethodWorker.java:146)
at org.testng.internal.TestMethodWorker.run(TestMethodWorker.java:128)
at java.base/java.util.ArrayList.forEach(ArrayList.java:1511)
at org.testng.TestRunner.privateRun(TestRunner.java:794)
at org.testng.TestRunner.run(TestRunner.java:596)
at org.testng.SuiteRunner.runTest(SuiteRunner.java:377)
at org.testng.SuiteRunner.runSequentially(SuiteRunner.java:371)
at org.testng.SuiteRunner.privateRun(SuiteRunner.java:332)
at org.testng.SuiteRunner.run(SuiteRunner.java:276)
at org.testng.SuiteRunnerWorker.runSuite(SuiteRunnerWorker.java:53)
at org.testng.SuiteRunnerWorker.run(SuiteRunnerWorker.java:96)
at org.testng.TestNG.runSuitesSequentially(TestNG.java:1212)
at org.testng.TestNG.runSuitesLocally(TestNG.java:1134)
at org.testng.TestNG.runSuites(TestNG.java:1063)
at org.testng.TestNG.run(TestNG.java:1031)
at org.testng.remote.AbstractRemoteTestNG.run(AbstractRemoteTestNG.java:115)
at org.testng.remote.RemoteTestNG.initAndRun(RemoteTestNG.java:251)
at org.testng.remote.RemoteTestNG.main(RemoteTestNG.java:77)
]]>
            </full-stacktrace>
          </exception> <!-- java.lang.AssertionError -->
          <reporter-output>
          </reporter-output>
        </test-method> <!-- Testcase4 -->
        <test-method signature="Testcase5()[pri:5, instance:testAddstudent.TestAddStudent@5bd03f44]" started-at="2021-05-27T21:19:51 ICT" name="Testcase5" finished-at="2021-05-27T21:20:00 ICT" duration-ms="9647" status="PASS">
          <reporter-output>
          </reporter-output>
        </test-method> <!-- Testcase5 -->
        <test-method signature="Testcase6()[pri:6, instance:testAddstudent.TestAddStudent@5bd03f44]" started-at="2021-05-27T21:20:00 ICT" name="Testcase6" finished-at="2021-05-27T21:20:10 ICT" duration-ms="9644" status="FAIL">
          <exception class="java.lang.AssertionError">
            <message>
              <![CDATA[expected [This account already exists] but found [This email has been survived]]]>
            </message>
            <full-stacktrace>
              <![CDATA[java.lang.AssertionError: expected [This account already exists] but found [This email has been survived]
at org.testng.Assert.fail(Assert.java:99)
at org.testng.Assert.failNotEquals(Assert.java:1037)
at org.testng.Assert.assertEqualsImpl(Assert.java:140)
at org.testng.Assert.assertEquals(Assert.java:122)
at org.testng.Assert.assertEquals(Assert.java:629)
at org.testng.Assert.assertEquals(Assert.java:639)
at testAddstudent.TestAddStudent.Testcase6(TestAddStudent.java:377)
at java.base/jdk.internal.reflect.NativeMethodAccessorImpl.invoke0(Native Method)
at java.base/jdk.internal.reflect.NativeMethodAccessorImpl.invoke(NativeMethodAccessorImpl.java:62)
at java.base/jdk.internal.reflect.DelegatingMethodAccessorImpl.invoke(DelegatingMethodAccessorImpl.java:43)
at java.base/java.lang.reflect.Method.invoke(Method.java:564)
at org.testng.internal.MethodInvocationHelper.invokeMethod(MethodInvocationHelper.java:133)
at org.testng.internal.TestInvoker.invokeMethod(TestInvoker.java:598)
at org.testng.internal.TestInvoker.invokeTestMethod(TestInvoker.java:173)
at org.testng.internal.MethodRunner.runInSequence(MethodRunner.java:46)
at org.testng.internal.TestInvoker$MethodInvocationAgent.invoke(TestInvoker.java:824)
at org.testng.internal.TestInvoker.invokeTestMethods(TestInvoker.java:146)
at org.testng.internal.TestMethodWorker.invokeTestMethods(TestMethodWorker.java:146)
at org.testng.internal.TestMethodWorker.run(TestMethodWorker.java:128)
at java.base/java.util.ArrayList.forEach(ArrayList.java:1511)
at org.testng.TestRunner.privateRun(TestRunner.java:794)
at org.testng.TestRunner.run(TestRunner.java:596)
at org.testng.SuiteRunner.runTest(SuiteRunner.java:377)
at org.testng.SuiteRunner.runSequentially(SuiteRunner.java:371)
at org.testng.SuiteRunner.privateRun(SuiteRunner.java:332)
at org.testng.SuiteRunner.run(SuiteRunner.java:276)
at org.testng.SuiteRunnerWorker.runSuite(SuiteRunnerWorker.java:53)
at org.testng.SuiteRunnerWorker.run(SuiteRunnerWorker.java:96)
at org.testng.TestNG.runSuitesSequentially(TestNG.java:1212)
at org.testng.TestNG.runSuitesLocally(TestNG.java:1134)
at org.testng.TestNG.runSuites(TestNG.java:1063)
at org.testng.TestNG.run(TestNG.java:1031)
at org.testng.remote.AbstractRemoteTestNG.run(AbstractRemoteTestNG.java:115)
at org.testng.remote.RemoteTestNG.initAndRun(RemoteTestNG.java:251)
at org.testng.remote.RemoteTestNG.main(RemoteTestNG.java:77)
]]>
            </full-stacktrace>
          </exception> <!-- java.lang.AssertionError -->
          <reporter-output>
          </reporter-output>
        </test-method> <!-- Testcase6 -->
        <test-method signature="Testcase7()[pri:7, instance:testAddstudent.TestAddStudent@5bd03f44]" started-at="2021-05-27T21:20:10 ICT" name="Testcase7" finished-at="2021-05-27T21:20:19 ICT" duration-ms="9654" status="FAIL">
          <exception class="java.lang.AssertionError">
            <message>
              <![CDATA[expected [This account already exists] but found [Add success]]]>
            </message>
            <full-stacktrace>
              <![CDATA[java.lang.AssertionError: expected [This account already exists] but found [Add success]
at org.testng.Assert.fail(Assert.java:99)
at org.testng.Assert.failNotEquals(Assert.java:1037)
at org.testng.Assert.assertEqualsImpl(Assert.java:140)
at org.testng.Assert.assertEquals(Assert.java:122)
at org.testng.Assert.assertEquals(Assert.java:629)
at org.testng.Assert.assertEquals(Assert.java:639)
at testAddstudent.TestAddStudent.Testcase7(TestAddStudent.java:428)
at java.base/jdk.internal.reflect.NativeMethodAccessorImpl.invoke0(Native Method)
at java.base/jdk.internal.reflect.NativeMethodAccessorImpl.invoke(NativeMethodAccessorImpl.java:62)
at java.base/jdk.internal.reflect.DelegatingMethodAccessorImpl.invoke(DelegatingMethodAccessorImpl.java:43)
at java.base/java.lang.reflect.Method.invoke(Method.java:564)
at org.testng.internal.MethodInvocationHelper.invokeMethod(MethodInvocationHelper.java:133)
at org.testng.internal.TestInvoker.invokeMethod(TestInvoker.java:598)
at org.testng.internal.TestInvoker.invokeTestMethod(TestInvoker.java:173)
at org.testng.internal.MethodRunner.runInSequence(MethodRunner.java:46)
at org.testng.internal.TestInvoker$MethodInvocationAgent.invoke(TestInvoker.java:824)
at org.testng.internal.TestInvoker.invokeTestMethods(TestInvoker.java:146)
at org.testng.internal.TestMethodWorker.invokeTestMethods(TestMethodWorker.java:146)
at org.testng.internal.TestMethodWorker.run(TestMethodWorker.java:128)
at java.base/java.util.ArrayList.forEach(ArrayList.java:1511)
at org.testng.TestRunner.privateRun(TestRunner.java:794)
at org.testng.TestRunner.run(TestRunner.java:596)
at org.testng.SuiteRunner.runTest(SuiteRunner.java:377)
at org.testng.SuiteRunner.runSequentially(SuiteRunner.java:371)
at org.testng.SuiteRunner.privateRun(SuiteRunner.java:332)
at org.testng.SuiteRunner.run(SuiteRunner.java:276)
at org.testng.SuiteRunnerWorker.runSuite(SuiteRunnerWorker.java:53)
at org.testng.SuiteRunnerWorker.run(SuiteRunnerWorker.java:96)
at org.testng.TestNG.runSuitesSequentially(TestNG.java:1212)
at org.testng.TestNG.runSuitesLocally(TestNG.java:1134)
at org.testng.TestNG.runSuites(TestNG.java:1063)
at org.testng.TestNG.run(TestNG.java:1031)
at org.testng.remote.AbstractRemoteTestNG.run(AbstractRemoteTestNG.java:115)
at org.testng.remote.RemoteTestNG.initAndRun(RemoteTestNG.java:251)
at org.testng.remote.RemoteTestNG.main(RemoteTestNG.java:77)
]]>
            </full-stacktrace>
          </exception> <!-- java.lang.AssertionError -->
          <reporter-output>
          </reporter-output>
        </test-method> <!-- Testcase7 -->
        <test-method is-config="true" signature="afterClass()[pri:0, instance:testAddstudent.TestAddStudent@5bd03f44]" started-at="2021-05-27T21:20:19 ICT" name="afterClass" finished-at="2021-05-27T21:20:20 ICT" duration-ms="678" status="PASS">
          <reporter-output>
          </reporter-output>
        </test-method> <!-- afterClass -->
      </class> <!-- testAddstudent.TestAddStudent -->
    </test> <!-- Default test -->
  </suite> <!-- Default suite -->
</testng-results>
